[2021-08-12 10:52:43,186] {taskinstance.py:896} INFO - Dependencies all met for <TaskInstance: parallel_dag_02.processing_tasks 2021-08-10T00:00:00+00:00 [queued]>
[2021-08-12 10:52:43,190] {taskinstance.py:896} INFO - Dependencies all met for <TaskInstance: parallel_dag_02.processing_tasks 2021-08-10T00:00:00+00:00 [queued]>
[2021-08-12 10:52:43,190] {taskinstance.py:1087} INFO - 
--------------------------------------------------------------------------------
[2021-08-12 10:52:43,190] {taskinstance.py:1088} INFO - Starting attempt 1 of 1
[2021-08-12 10:52:43,190] {taskinstance.py:1089} INFO - 
--------------------------------------------------------------------------------
[2021-08-12 10:52:43,196] {taskinstance.py:1107} INFO - Executing <Task(SubDagOperator): processing_tasks> on 2021-08-10T00:00:00+00:00
[2021-08-12 10:52:43,198] {standard_task_runner.py:52} INFO - Started process 154161 to run task
[2021-08-12 10:52:43,201] {standard_task_runner.py:76} INFO - Running: ['airflow', 'tasks', 'run', 'parallel_dag_02', 'processing_tasks', '2021-08-10T00:00:00+00:00', '--job-id', '47', '--pool', 'default_pool', '--raw', '--subdir', 'DAGS_FOLDER/subdag_example_02.py', '--cfg-path', '/tmp/tmpceblsph5', '--error-file', '/tmp/tmp27hobre3']
[2021-08-12 10:52:43,201] {standard_task_runner.py:77} INFO - Job 47: Subtask processing_tasks
[2021-08-12 10:52:43,222] {logging_mixin.py:104} INFO - Running <TaskInstance: parallel_dag_02.processing_tasks 2021-08-10T00:00:00+00:00 [running]> on host adam
[2021-08-12 10:52:43,244] {taskinstance.py:1300} INFO - Exporting the following env vars:
AIRFLOW_CTX_DAG_OWNER=airflow
AIRFLOW_CTX_DAG_ID=parallel_dag_02
AIRFLOW_CTX_TASK_ID=processing_tasks
AIRFLOW_CTX_EXECUTION_DATE=2021-08-10T00:00:00+00:00
AIRFLOW_CTX_DAG_RUN_ID=scheduled__2021-08-10T00:00:00+00:00
[2021-08-12 10:52:43,253] {subdag.py:155} INFO - Created DagRun: scheduled__2021-08-10T00:00:00+00:00
[2021-08-12 10:53:53,309] {process_utils.py:100} INFO - Sending Signals.SIGTERM to GPID 154161
[2021-08-12 10:53:53,309] {taskinstance.py:1284} ERROR - Received SIGTERM. Terminating subprocesses.
[2021-08-12 10:53:53,314] {taskinstance.py:1501} ERROR - Task failed with exception
Traceback (most recent call last):
  File "/home/adam/.virtualenvs/airflow_telia/lib/python3.9/site-packages/airflow/models/taskinstance.py", line 1157, in _run_raw_task
    self._prepare_and_execute_task_with_callbacks(context, task)
  File "/home/adam/.virtualenvs/airflow_telia/lib/python3.9/site-packages/airflow/models/taskinstance.py", line 1331, in _prepare_and_execute_task_with_callbacks
    result = self._execute_task(context, task_copy)
  File "/home/adam/.virtualenvs/airflow_telia/lib/python3.9/site-packages/airflow/models/taskinstance.py", line 1361, in _execute_task
    result = task_copy.execute(context=context)
  File "/home/adam/.virtualenvs/airflow_telia/lib/python3.9/site-packages/airflow/sensors/base.py", line 246, in execute
    time.sleep(self._get_next_poke_interval(started_at, run_duration, try_number))
  File "/home/adam/.virtualenvs/airflow_telia/lib/python3.9/site-packages/airflow/models/taskinstance.py", line 1286, in signal_handler
    raise AirflowException("Task received SIGTERM signal")
airflow.exceptions.AirflowException: Task received SIGTERM signal
[2021-08-12 10:53:53,317] {taskinstance.py:1544} INFO - Marking task as FAILED. dag_id=parallel_dag_02, task_id=processing_tasks, execution_date=20210810T000000, start_date=20210812T085243, end_date=20210812T085353
[2021-08-12 10:53:53,336] {process_utils.py:66} INFO - Process psutil.Process(pid=154161, status='terminated', exitcode=1, started='10:52:42') (154161) terminated with exit code 1
[2021-08-12 10:58:19,784] {taskinstance.py:896} INFO - Dependencies all met for <TaskInstance: parallel_dag_02.processing_tasks 2021-08-10T00:00:00+00:00 [queued]>
[2021-08-12 10:58:19,789] {taskinstance.py:896} INFO - Dependencies all met for <TaskInstance: parallel_dag_02.processing_tasks 2021-08-10T00:00:00+00:00 [queued]>
[2021-08-12 10:58:19,789] {taskinstance.py:1087} INFO - 
--------------------------------------------------------------------------------
[2021-08-12 10:58:19,789] {taskinstance.py:1088} INFO - Starting attempt 1 of 1
[2021-08-12 10:58:19,789] {taskinstance.py:1089} INFO - 
--------------------------------------------------------------------------------
[2021-08-12 10:58:19,795] {taskinstance.py:1107} INFO - Executing <Task(SubDagOperator): processing_tasks> on 2021-08-10T00:00:00+00:00
[2021-08-12 10:58:19,796] {standard_task_runner.py:52} INFO - Started process 161344 to run task
[2021-08-12 10:58:19,800] {standard_task_runner.py:76} INFO - Running: ['airflow', 'tasks', 'run', 'parallel_dag_02', 'processing_tasks', '2021-08-10T00:00:00+00:00', '--job-id', '58', '--pool', 'default_pool', '--raw', '--subdir', 'DAGS_FOLDER/subdag_example_02.py', '--cfg-path', '/tmp/tmpi789l5if', '--error-file', '/tmp/tmpp_e10_fr']
[2021-08-12 10:58:19,800] {standard_task_runner.py:77} INFO - Job 58: Subtask processing_tasks
[2021-08-12 10:58:19,845] {logging_mixin.py:104} INFO - Running <TaskInstance: parallel_dag_02.processing_tasks 2021-08-10T00:00:00+00:00 [running]> on host adam
[2021-08-12 10:58:19,868] {taskinstance.py:1300} INFO - Exporting the following env vars:
AIRFLOW_CTX_DAG_OWNER=airflow
AIRFLOW_CTX_DAG_ID=parallel_dag_02
AIRFLOW_CTX_TASK_ID=processing_tasks
AIRFLOW_CTX_EXECUTION_DATE=2021-08-10T00:00:00+00:00
AIRFLOW_CTX_DAG_RUN_ID=scheduled__2021-08-10T00:00:00+00:00
[2021-08-12 10:58:19,880] {subdag.py:155} INFO - Created DagRun: scheduled__2021-08-10T00:00:00+00:00
[2021-08-12 11:05:20,823] {process_utils.py:100} INFO - Sending Signals.SIGTERM to GPID 161344
[2021-08-12 11:05:20,823] {taskinstance.py:1284} ERROR - Received SIGTERM. Terminating subprocesses.
[2021-08-12 11:05:20,827] {taskinstance.py:1501} ERROR - Task failed with exception
Traceback (most recent call last):
  File "/home/adam/.virtualenvs/airflow_telia/lib/python3.9/site-packages/airflow/models/taskinstance.py", line 1157, in _run_raw_task
    self._prepare_and_execute_task_with_callbacks(context, task)
  File "/home/adam/.virtualenvs/airflow_telia/lib/python3.9/site-packages/airflow/models/taskinstance.py", line 1331, in _prepare_and_execute_task_with_callbacks
    result = self._execute_task(context, task_copy)
  File "/home/adam/.virtualenvs/airflow_telia/lib/python3.9/site-packages/airflow/models/taskinstance.py", line 1361, in _execute_task
    result = task_copy.execute(context=context)
  File "/home/adam/.virtualenvs/airflow_telia/lib/python3.9/site-packages/airflow/sensors/base.py", line 246, in execute
    time.sleep(self._get_next_poke_interval(started_at, run_duration, try_number))
  File "/home/adam/.virtualenvs/airflow_telia/lib/python3.9/site-packages/airflow/models/taskinstance.py", line 1286, in signal_handler
    raise AirflowException("Task received SIGTERM signal")
airflow.exceptions.AirflowException: Task received SIGTERM signal
[2021-08-12 11:05:20,829] {taskinstance.py:1544} INFO - Marking task as FAILED. dag_id=parallel_dag_02, task_id=processing_tasks, execution_date=20210810T000000, start_date=20210812T085819, end_date=20210812T090520
[2021-08-12 11:05:20,850] {process_utils.py:66} INFO - Process psutil.Process(pid=161344, status='terminated', exitcode=1, started='10:58:19') (161344) terminated with exit code 1
[2021-08-12 11:06:36,008] {taskinstance.py:896} INFO - Dependencies all met for <TaskInstance: parallel_dag_02.processing_tasks 2021-08-10T00:00:00+00:00 [queued]>
[2021-08-12 11:06:36,013] {taskinstance.py:896} INFO - Dependencies all met for <TaskInstance: parallel_dag_02.processing_tasks 2021-08-10T00:00:00+00:00 [queued]>
[2021-08-12 11:06:36,013] {taskinstance.py:1087} INFO - 
--------------------------------------------------------------------------------
[2021-08-12 11:06:36,013] {taskinstance.py:1088} INFO - Starting attempt 1 of 1
[2021-08-12 11:06:36,013] {taskinstance.py:1089} INFO - 
--------------------------------------------------------------------------------
[2021-08-12 11:06:36,019] {taskinstance.py:1107} INFO - Executing <Task(SubDagOperator): processing_tasks> on 2021-08-10T00:00:00+00:00
[2021-08-12 11:06:36,021] {standard_task_runner.py:52} INFO - Started process 172112 to run task
[2021-08-12 11:06:36,024] {standard_task_runner.py:76} INFO - Running: ['airflow', 'tasks', 'run', 'parallel_dag_02', 'processing_tasks', '2021-08-10T00:00:00+00:00', '--job-id', '67', '--pool', 'default_pool', '--raw', '--subdir', 'DAGS_FOLDER/subdag_example_02.py', '--cfg-path', '/tmp/tmp7wj4i99k', '--error-file', '/tmp/tmp7es8ezbq']
[2021-08-12 11:06:36,025] {standard_task_runner.py:77} INFO - Job 67: Subtask processing_tasks
[2021-08-12 11:06:36,044] {logging_mixin.py:104} INFO - Running <TaskInstance: parallel_dag_02.processing_tasks 2021-08-10T00:00:00+00:00 [running]> on host adam
[2021-08-12 11:06:36,063] {taskinstance.py:1300} INFO - Exporting the following env vars:
AIRFLOW_CTX_DAG_OWNER=airflow
AIRFLOW_CTX_DAG_ID=parallel_dag_02
AIRFLOW_CTX_TASK_ID=processing_tasks
AIRFLOW_CTX_EXECUTION_DATE=2021-08-10T00:00:00+00:00
AIRFLOW_CTX_DAG_RUN_ID=scheduled__2021-08-10T00:00:00+00:00
[2021-08-12 11:06:36,071] {subdag.py:155} INFO - Created DagRun: scheduled__2021-08-10T00:00:00+00:00
[2021-08-12 14:50:49,863] {local_task_job.py:197} WARNING - State of this instance has been externally set to None. Terminating instance.
[2021-08-12 14:50:49,879] {process_utils.py:100} INFO - Sending Signals.SIGTERM to GPID 172112
[2021-08-12 14:50:49,880] {taskinstance.py:1284} ERROR - Received SIGTERM. Terminating subprocesses.
[2021-08-12 14:50:49,883] {taskinstance.py:1501} ERROR - Task failed with exception
Traceback (most recent call last):
  File "/home/adam/.virtualenvs/airflow_telia/lib/python3.9/site-packages/airflow/models/taskinstance.py", line 1157, in _run_raw_task
    self._prepare_and_execute_task_with_callbacks(context, task)
  File "/home/adam/.virtualenvs/airflow_telia/lib/python3.9/site-packages/airflow/models/taskinstance.py", line 1331, in _prepare_and_execute_task_with_callbacks
    result = self._execute_task(context, task_copy)
  File "/home/adam/.virtualenvs/airflow_telia/lib/python3.9/site-packages/airflow/models/taskinstance.py", line 1361, in _execute_task
    result = task_copy.execute(context=context)
  File "/home/adam/.virtualenvs/airflow_telia/lib/python3.9/site-packages/airflow/sensors/base.py", line 246, in execute
    time.sleep(self._get_next_poke_interval(started_at, run_duration, try_number))
  File "/home/adam/.virtualenvs/airflow_telia/lib/python3.9/site-packages/airflow/models/taskinstance.py", line 1286, in signal_handler
    raise AirflowException("Task received SIGTERM signal")
airflow.exceptions.AirflowException: Task received SIGTERM signal
[2021-08-12 14:50:49,885] {taskinstance.py:1544} INFO - Marking task as FAILED. dag_id=parallel_dag_02, task_id=processing_tasks, execution_date=20210810T000000, start_date=20210812T090636, end_date=20210812T125049
[2021-08-12 14:50:49,932] {process_utils.py:66} INFO - Process psutil.Process(pid=172112, status='terminated', exitcode=1, started='11:06:35') (172112) terminated with exit code 1
