[2021-08-12 10:53:59,162] {taskinstance.py:896} INFO - Dependencies all met for <TaskInstance: parallel_dag_02.processing_tasks 2021-08-11T00:00:00+00:00 [queued]>
[2021-08-12 10:53:59,167] {taskinstance.py:896} INFO - Dependencies all met for <TaskInstance: parallel_dag_02.processing_tasks 2021-08-11T00:00:00+00:00 [queued]>
[2021-08-12 10:53:59,167] {taskinstance.py:1087} INFO - 
--------------------------------------------------------------------------------
[2021-08-12 10:53:59,167] {taskinstance.py:1088} INFO - Starting attempt 1 of 1
[2021-08-12 10:53:59,167] {taskinstance.py:1089} INFO - 
--------------------------------------------------------------------------------
[2021-08-12 10:53:59,173] {taskinstance.py:1107} INFO - Executing <Task(SubDagOperator): processing_tasks> on 2021-08-11T00:00:00+00:00
[2021-08-12 10:53:59,175] {standard_task_runner.py:52} INFO - Started process 155837 to run task
[2021-08-12 10:53:59,179] {standard_task_runner.py:76} INFO - Running: ['airflow', 'tasks', 'run', 'parallel_dag_02', 'processing_tasks', '2021-08-11T00:00:00+00:00', '--job-id', '51', '--pool', 'default_pool', '--raw', '--subdir', 'DAGS_FOLDER/subdag_example_02.py', '--cfg-path', '/tmp/tmp0zr_s99m', '--error-file', '/tmp/tmpf3afss5q']
[2021-08-12 10:53:59,179] {standard_task_runner.py:77} INFO - Job 51: Subtask processing_tasks
[2021-08-12 10:53:59,207] {logging_mixin.py:104} INFO - Running <TaskInstance: parallel_dag_02.processing_tasks 2021-08-11T00:00:00+00:00 [running]> on host adam
[2021-08-12 10:53:59,233] {taskinstance.py:1300} INFO - Exporting the following env vars:
AIRFLOW_CTX_DAG_OWNER=airflow
AIRFLOW_CTX_DAG_ID=parallel_dag_02
AIRFLOW_CTX_TASK_ID=processing_tasks
AIRFLOW_CTX_EXECUTION_DATE=2021-08-11T00:00:00+00:00
AIRFLOW_CTX_DAG_RUN_ID=scheduled__2021-08-11T00:00:00+00:00
[2021-08-12 10:53:59,243] {subdag.py:155} INFO - Created DagRun: scheduled__2021-08-11T00:00:00+00:00
[2021-08-12 10:57:18,090] {process_utils.py:100} INFO - Sending Signals.SIGTERM to GPID 155837
[2021-08-12 10:57:18,090] {taskinstance.py:1284} ERROR - Received SIGTERM. Terminating subprocesses.
[2021-08-12 10:57:18,096] {taskinstance.py:1501} ERROR - Task failed with exception
Traceback (most recent call last):
  File "/home/adam/.virtualenvs/airflow_telia/lib/python3.9/site-packages/airflow/models/taskinstance.py", line 1157, in _run_raw_task
    self._prepare_and_execute_task_with_callbacks(context, task)
  File "/home/adam/.virtualenvs/airflow_telia/lib/python3.9/site-packages/airflow/models/taskinstance.py", line 1331, in _prepare_and_execute_task_with_callbacks
    result = self._execute_task(context, task_copy)
  File "/home/adam/.virtualenvs/airflow_telia/lib/python3.9/site-packages/airflow/models/taskinstance.py", line 1361, in _execute_task
    result = task_copy.execute(context=context)
  File "/home/adam/.virtualenvs/airflow_telia/lib/python3.9/site-packages/airflow/sensors/base.py", line 246, in execute
    time.sleep(self._get_next_poke_interval(started_at, run_duration, try_number))
  File "/home/adam/.virtualenvs/airflow_telia/lib/python3.9/site-packages/airflow/models/taskinstance.py", line 1286, in signal_handler
    raise AirflowException("Task received SIGTERM signal")
airflow.exceptions.AirflowException: Task received SIGTERM signal
[2021-08-12 10:57:18,098] {taskinstance.py:1544} INFO - Marking task as FAILED. dag_id=parallel_dag_02, task_id=processing_tasks, execution_date=20210811T000000, start_date=20210812T085359, end_date=20210812T085718
[2021-08-12 10:57:18,117] {process_utils.py:66} INFO - Process psutil.Process(pid=155837, status='terminated', exitcode=1, started='10:53:58') (155837) terminated with exit code 1
[2021-08-12 11:05:28,063] {taskinstance.py:896} INFO - Dependencies all met for <TaskInstance: parallel_dag_02.processing_tasks 2021-08-11T00:00:00+00:00 [queued]>
[2021-08-12 11:05:28,069] {taskinstance.py:896} INFO - Dependencies all met for <TaskInstance: parallel_dag_02.processing_tasks 2021-08-11T00:00:00+00:00 [queued]>
[2021-08-12 11:05:28,070] {taskinstance.py:1087} INFO - 
--------------------------------------------------------------------------------
[2021-08-12 11:05:28,070] {taskinstance.py:1088} INFO - Starting attempt 1 of 1
[2021-08-12 11:05:28,070] {taskinstance.py:1089} INFO - 
--------------------------------------------------------------------------------
[2021-08-12 11:05:28,076] {taskinstance.py:1107} INFO - Executing <Task(SubDagOperator): processing_tasks> on 2021-08-11T00:00:00+00:00
[2021-08-12 11:05:28,079] {standard_task_runner.py:52} INFO - Started process 170697 to run task
[2021-08-12 11:05:28,083] {standard_task_runner.py:76} INFO - Running: ['airflow', 'tasks', 'run', 'parallel_dag_02', 'processing_tasks', '2021-08-11T00:00:00+00:00', '--job-id', '62', '--pool', 'default_pool', '--raw', '--subdir', 'DAGS_FOLDER/subdag_example_02.py', '--cfg-path', '/tmp/tmpppxaku89', '--error-file', '/tmp/tmphz7yzx9u']
[2021-08-12 11:05:28,084] {standard_task_runner.py:77} INFO - Job 62: Subtask processing_tasks
[2021-08-12 11:05:28,110] {logging_mixin.py:104} INFO - Running <TaskInstance: parallel_dag_02.processing_tasks 2021-08-11T00:00:00+00:00 [running]> on host adam
[2021-08-12 11:05:28,135] {taskinstance.py:1300} INFO - Exporting the following env vars:
AIRFLOW_CTX_DAG_OWNER=airflow
AIRFLOW_CTX_DAG_ID=parallel_dag_02
AIRFLOW_CTX_TASK_ID=processing_tasks
AIRFLOW_CTX_EXECUTION_DATE=2021-08-11T00:00:00+00:00
AIRFLOW_CTX_DAG_RUN_ID=scheduled__2021-08-11T00:00:00+00:00
[2021-08-12 11:05:28,145] {subdag.py:155} INFO - Created DagRun: scheduled__2021-08-11T00:00:00+00:00
[2021-08-12 11:05:43,257] {local_task_job.py:197} WARNING - State of this instance has been externally set to None. Terminating instance.
[2021-08-12 11:05:43,271] {process_utils.py:100} INFO - Sending Signals.SIGTERM to GPID 170697
[2021-08-12 11:05:43,271] {taskinstance.py:1284} ERROR - Received SIGTERM. Terminating subprocesses.
[2021-08-12 11:05:43,279] {taskinstance.py:1501} ERROR - Task failed with exception
Traceback (most recent call last):
  File "/home/adam/.virtualenvs/airflow_telia/lib/python3.9/site-packages/airflow/models/taskinstance.py", line 1157, in _run_raw_task
    self._prepare_and_execute_task_with_callbacks(context, task)
  File "/home/adam/.virtualenvs/airflow_telia/lib/python3.9/site-packages/airflow/models/taskinstance.py", line 1331, in _prepare_and_execute_task_with_callbacks
    result = self._execute_task(context, task_copy)
  File "/home/adam/.virtualenvs/airflow_telia/lib/python3.9/site-packages/airflow/models/taskinstance.py", line 1361, in _execute_task
    result = task_copy.execute(context=context)
  File "/home/adam/.virtualenvs/airflow_telia/lib/python3.9/site-packages/airflow/sensors/base.py", line 246, in execute
    time.sleep(self._get_next_poke_interval(started_at, run_duration, try_number))
  File "/home/adam/.virtualenvs/airflow_telia/lib/python3.9/site-packages/airflow/models/taskinstance.py", line 1286, in signal_handler
    raise AirflowException("Task received SIGTERM signal")
airflow.exceptions.AirflowException: Task received SIGTERM signal
[2021-08-12 11:05:43,283] {taskinstance.py:1544} INFO - Marking task as FAILED. dag_id=parallel_dag_02, task_id=processing_tasks, execution_date=20210811T000000, start_date=20210812T090528, end_date=20210812T090543
[2021-08-12 11:05:43,323] {process_utils.py:66} INFO - Process psutil.Process(pid=170697, status='terminated', exitcode=1, started='11:05:27') (170697) terminated with exit code 1
